<?xml version="1.0" ?>
<sdf version="1.9">
  <model name="blueye" canonical_link="blueye_link">
    <link name="blueye_link">
      <!--Main model link-->
      <pose relative_to="__model__">0.0 0.0 0.0 0.0 0.0 0.0</pose>
      <visual name="blueye_visual">
        <pose relative_to="blueye_link">-0.31 -0.1285 -0.177 1.5707 0.0 1.5707</pose>
        <geometry>
          <mesh>
            <uri>model://models/dynamic_assets/blueye/meshes/blueye.dae</uri>
            <scale>1 1 1</scale>
          </mesh>
        </geometry>
      </visual>
      <inertial>
        <mass>8.6</mass>
        <pose>0.0 0.0 0.0 0.0 0.0 0.0</pose>
        <inertia>
          <ixx>10000</ixx>
          <ixy>0</ixy>
          <ixz>0</ixz>
          <iyy>10000</iyy>
          <iyz>0</iyz>
          <izz>100</izz>
        </inertia>
        <fluid_added_mass>
          <xx>5.2171</xx>
          <yy>19.8729</yy>
          <zz>11.2643</zz>
          <pp>0.0972</pp>
          <qq>0.1822</qq>
          <rr>0.1594</rr>
        </fluid_added_mass>
      </inertial>
      <collision name="blueye_collision">
        <!--Collision box for bouyancy-->
        <pose relative_to="blueye_link">0.0 0.0 0.1 0.0 0.0 0.0</pose>
        <geometry>
          <box>
            <size>0.409 0.205 0.1025</size>
          </box>
        </geometry>
      </collision>
    </link>
    <plugin name="gz::sim::systems::OdometryPublisher" filename="gz-sim-odometry-publisher-system">
      <!--Ground Truth Position-->
      <frame>world_flu</frame>
      <robot_base_frame>blueye_link</robot_base_frame>
      <odom_topic>blueye/odometry_flu/gt</odom_topic>
      <dimensions>3</dimensions>
    </plugin>
    <link name="blueye_light_link">
      <!--Blueye Light Link-->
      <pose relative_to="blueye_link">0.0 0.0 0.0 0.0 0.0 0.0</pose>
      <light name="blueye_light" type="spot">
        <pose>0.0 0.0 0.0 0.0 0.0 0.0</pose>
        <diffuse>1.0 1.0 1.0 1.0</diffuse>
        <specular>0.5 0.5 0.5 1.0</specular>
        <attenuation>
          <range>20.0</range>
          <constant>0.5</constant>
          <linear>1.0</linear>
          <quadratic>0.3</quadratic>
        </attenuation>
        <direction>1.0 0.0 0.0</direction>
        <cast_shadows>1</cast_shadows>
        <spot>
          <inner_angle>1.0</inner_angle>
          <outer_angle>1.0</outer_angle>
          <falloff>1.0</falloff>
        </spot>
      </light>
      <inertial>
        <mass>0.0001</mass>
      </inertial>
    </link>
    <joint name="blueye_light_joint" type="fixed">
      <!--Blueye Light Joint-->
      <child>blueye_light_link</child>
      <parent>blueye_link</parent>
    </joint>
    <link name="blueye_imu_link">
      <!--IMU Sensor Link-->
      <pose relative_to="blueye_link">0.0 0.0 0.0 0.0 0.0 0.0</pose>
      <sensor name="blueye_imu" type="imu">
        <update_rate>500</update_rate>
        <topic>/blueye/imu</topic>
        <imu>
          <linear_acceleration>
            <x>
              <noise type="gaussian">
                <mean>0.0</mean>
                <stddev>0.01</stddev>
                <bias_mean>0.0</bias_mean>
                <bias_stddev>0.0</bias_stddev>
              </noise>
            </x>
            <y>
              <noise type="gaussian">
                <mean>0.0</mean>
                <stddev>0.01</stddev>
                <bias_mean>0.0</bias_mean>
                <bias_stddev>0.0</bias_stddev>
              </noise>
            </y>
            <z>
              <noise type="gaussian">
                <mean>0.0</mean>
                <stddev>0.01</stddev>
                <bias_mean>0.0</bias_mean>
                <bias_stddev>0.0</bias_stddev>
              </noise>
            </z>
          </linear_acceleration>
          <angular_velocity>
            <x>
              <noise type="gaussian">
                <mean>0.0</mean>
                <stddev>0.01</stddev>
                <bias_mean>0.0</bias_mean>
                <bias_stddev>0.0</bias_stddev>
              </noise>
            </x>
            <y>
              <noise type="gaussian">
                <mean>0.0</mean>
                <stddev>0.01</stddev>
                <bias_mean>0.0</bias_mean>
                <bias_stddev>0.0</bias_stddev>
              </noise>
            </y>
            <z>
              <noise type="gaussian">
                <mean>0.0</mean>
                <stddev>0.01</stddev>
                <bias_mean>0.0</bias_mean>
                <bias_stddev>0.0</bias_stddev>
              </noise>
            </z>
          </angular_velocity>
        </imu>
        <always_on>1</always_on>
      </sensor>
      <inertial>
        <mass>0.0001</mass>
      </inertial>
    </link>
    <joint name="blueye_imu_joint" type="fixed">
      <!--IMU Joint-->
      <child>blueye_imu_link</child>
      <parent>blueye_link</parent>
    </joint>
    <link name="blueye_camera_1_link">
      <!--Camera 1 Link-->
      <pose relative_to="blueye_link">0.3 0.3 0.0 0.0 0.0 0.0</pose>
      <sensor name="blueye_camera_1" type="camera">
        <camera>
          <image>
            <width>1920</width>
            <height>1080</height>
          </image>
          <horizontal_fov>1.0472</horizontal_fov>
          <clip>
            <far>20.0</far>
            <near>0.1</near>
          </clip>
          <camera_info_topic>/blueye/camera_1/camera_info</camera_info_topic>
        </camera>
        <always_on>1</always_on>
        <update_rate>10</update_rate>
        <topic>/blueye/camera_1/image_raw</topic>
        <visualize>1</visualize>
      </sensor>
      <inertial>
        <mass>0.0001</mass>
      </inertial>
    </link>
    <joint name="blueye_camera_1_joint" type="fixed">
      <!--Camera 1 Joint-->
      <child>blueye_camera_1_link</child>
      <parent>blueye_link</parent>
    </joint>
    <link name="blueye_depth_camera_link">
      <!--Depth Camera Link-->
      <pose relative_to="blueye_link">0.0 0.0 0.0 0.0 0.0 0.0</pose>
      <sensor name="blueye_depth_camera" type="depth_camera">
        <camera>
          <image>
            <width>320</width>
            <height>240</height>
          </image>
          <horizontal_fov>1.0472</horizontal_fov>
          <clip>
            <far>20.0</far>
            <near>0.1</near>
          </clip>
          <camera_info_topic>/blueye/depth_camera/camera_info</camera_info_topic>
          <depth_camera>
            <output>/blueye/depth_camera/output</output>
            <clip>
              <near>0.1</near>
              <far>30.0</far>
            </clip>
          </depth_camera>
          <intrinsics/>
        </camera>
        <always_on>1</always_on>
        <update_rate>10</update_rate>
        <topic>/blueye/depth_camera/image_raw</topic>
        <visualize>1</visualize>
      </sensor>
      <inertial>
        <mass>0.0001</mass>
      </inertial>
    </link>
    <joint name="blueye_depth_camera_joint" type="fixed">
      <!--Depth Camera Joint-->
      <child>blueye_depth_camera_link</child>
      <parent>blueye_link</parent>
    </joint>
    <link name="blueye_dvl_ray_link">
      <!--DVL Ray Link-->
      <pose relative_to="blueye_link">0.0 0.0 0.0 0.0 1.5758 0.0</pose>
      <sensor name="blueye_dvl_ray" type="gpu_lidar">
        <always_on>1</always_on>
        <update_rate>10</update_rate>
        <topic>/blueye/dvl/ray</topic>
        <visualize>1</visualize>
        <ray>
          <scan>
            <horizontal>
              <samples>1</samples>
              <resolution>1</resolution>
              <min_angle>-0.1</min_angle>
              <max_angle>0.1</max_angle>
            </horizontal>
            <vertical>
              <samples>1</samples>
              <resolution>1</resolution>
              <min_angle>-0.1</min_angle>
              <max_angle>0.1</max_angle>
            </vertical>
          </scan>
          <range>
            <min>0.1</min>
            <max>30.0</max>
            <resolution>0.1</resolution>
          </range>
          <noise>
            <type>gaussian</type>
            <mean>0.0</mean>
            <stddev>0.2</stddev>
          </noise>
        </ray>
      </sensor>
      <inertial>
        <mass>0.0001</mass>
      </inertial>
    </link>
    <joint name="blueye_dvl_ray_joint" type="fixed">
      <!--DVL Ray Joint-->
      <child>blueye_dvl_ray_link</child>
      <parent>blueye_link</parent>
    </joint>
    <link name="blueye_thruster_1_link">
      <!--Thruster 1 Link-->
      <pose relative_to="blueye_link">-0.14 0.0815 -0.004 0.0 -1.5707 0.0</pose>
      <visual name="blueye_thruster_1_visual">
        <pose relative_to="blueye_link">-0.14 0.0815 -0.004 0.0 -3.1415 0.0</pose>
        <geometry>
          <mesh>
            <uri>model://models/dynamic_assets/blueye/meshes/prop.dae</uri>
            <scale>0.7 0.7 0.7</scale>
          </mesh>
        </geometry>
      </visual>
      <inertial>
        <mass>0.0001</mass>
      </inertial>
    </link>
    <joint name="blueye_thruster_1_joint" type="revolute">
      <!--Thruster 1 Joint-->
      <child>blueye_thruster_1_link</child>
      <parent>blueye_link</parent>
      <axis>
        <xyz>0 0 -1</xyz>
        <limit>
          <lower>-1e+16</lower>
          <upper>1e+16</upper>
        </limit>
      </axis>
    </joint>
    <plugin name="gz::sim::systems::Thruster" filename="gz-sim-thruster-system">
      <namespace>blueye</namespace>
      <joint_name>blueye_thruster_1_joint</joint_name>
      <fluid_density>1025</fluid_density>
      <propeller_diameter>0.2</propeller_diameter>
      <max_thrust_cmd>1200</max_thrust_cmd>
      <min_thrust_cmd>-1200</min_thrust_cmd>
    </plugin>
    <link name="blueye_thruster_2_link">
      <!--Thruster 1 Link-->
      <pose relative_to="blueye_link">-0.14 -0.0785 -0.004 0.0 -1.5707 0.0</pose>
      <visual name="blueye_thruster_2_visual">
        <pose relative_to="blueye_link">-0.14 -0.0785 -0.004 0.0 -3.1415 0.0</pose>
        <geometry>
          <mesh>
            <uri>model://models/dynamic_assets/blueye/meshes/prop.dae</uri>
            <scale>0.7 0.7 0.7</scale>
          </mesh>
        </geometry>
      </visual>
      <inertial>
        <mass>0.0001</mass>
      </inertial>
    </link>
    <joint name="blueye_thruster_2_joint" type="revolute">
      <!--Thruster 1 Joint-->
      <child>blueye_thruster_2_link</child>
      <parent>blueye_link</parent>
      <axis>
        <xyz>0 0 -1</xyz>
        <limit>
          <lower>-1e+16</lower>
          <upper>1e+16</upper>
        </limit>
      </axis>
    </joint>
    <plugin name="gz::sim::systems::Thruster" filename="gz-sim-thruster-system">
      <namespace>blueye</namespace>
      <joint_name>blueye_thruster_2_joint</joint_name>
      <fluid_density>1025</fluid_density>
      <propeller_diameter>0.2</propeller_diameter>
      <max_thrust_cmd>1200</max_thrust_cmd>
      <min_thrust_cmd>-1200</min_thrust_cmd>
    </plugin>
    <link name="blueye_thruster_3_link">
      <!--Thruster 1 Link-->
      <pose relative_to="blueye_link">0.08 -0.034 -0.004 0.0 1.57 -1.57</pose>
      <visual name="blueye_thruster_3_visual">
        <pose>0.0 0.0 0.0 0.0 -1.5707 0.0</pose>
        <geometry>
          <mesh>
            <uri>model://models/dynamic_assets/blueye/meshes/prop.dae</uri>
            <scale>0.7 0.7 0.7</scale>
          </mesh>
        </geometry>
      </visual>
      <inertial>
        <mass>0.0001</mass>
      </inertial>
    </link>
    <joint name="blueye_thruster_3_joint" type="revolute">
      <!--Thruster 1 Joint-->
      <child>blueye_thruster_3_link</child>
      <parent>blueye_link</parent>
      <axis>
        <xyz>0 0 -1</xyz>
        <limit>
          <lower>-1e+16</lower>
          <upper>1e+16</upper>
        </limit>
      </axis>
    </joint>
    <plugin name="gz::sim::systems::Thruster" filename="gz-sim-thruster-system">
      <namespace>blueye</namespace>
      <joint_name>blueye_thruster_3_joint</joint_name>
      <fluid_density>1025</fluid_density>
      <propeller_diameter>0.2</propeller_diameter>
      <max_thrust_cmd>1200</max_thrust_cmd>
      <min_thrust_cmd>-1200</min_thrust_cmd>
    </plugin>
    <link name="blueye_thruster_4_link">
      <!--Thruster 1 Link-->
      <pose relative_to="blueye_link">0.0 0.0015 0.071 0.0 0.0 3.1415</pose>
      <visual name="blueye_thruster_4_visual">
        <pose>0.0 0.0 0.0 0.0 -1.5707 0.0</pose>
        <geometry>
          <mesh>
            <uri>model://models/dynamic_assets/blueye/meshes/prop.dae</uri>
            <scale>0.7 0.7 0.7</scale>
          </mesh>
        </geometry>
      </visual>
      <inertial>
        <mass>0.0001</mass>
      </inertial>
    </link>
    <joint name="blueye_thruster_4_joint" type="revolute">
      <!--Thruster 1 Joint-->
      <child>blueye_thruster_4_link</child>
      <parent>blueye_link</parent>
      <axis>
        <xyz>0 0 -1</xyz>
        <limit>
          <lower>-1e+16</lower>
          <upper>1e+16</upper>
        </limit>
      </axis>
    </joint>
    <plugin name="gz::sim::systems::Thruster" filename="gz-sim-thruster-system">
      <namespace>blueye</namespace>
      <joint_name>blueye_thruster_4_joint</joint_name>
      <fluid_density>1025</fluid_density>
      <propeller_diameter>0.2</propeller_diameter>
      <max_thrust_cmd>1200</max_thrust_cmd>
      <min_thrust_cmd>-1200</min_thrust_cmd>
    </plugin>
    <plugin name="gz::sim::systems::Hydrodynamics" filename="gz-sim-hydrodynamics-system">
      <!--Hydrodynamic Plugin-->
      <link_name>
        blueye_link
        <!--Linear Damping-->
      </link_name>
      <xU>-1.8430</xU>
      <yV>-3.1802</yV>
      <zW>-0.3778</zW>
      <kP>-0.868</kP>
      <mQ>-0.868</mQ>
      <nR>
        -0.868
        <!--Quadratic Damping-->
      </nR>
      <xUabsU>-9.4873</xUabsU>
      <yVabsV>-45.7127</yVabsV>
      <zWabsW>-25.4825</zWabsW>
      <kPabsP>-1.5344</kPabsP>
      <mQabsQ>-1.5344</mQabsQ>
      <nRabsR>-1.5344</nRabsR>
    </plugin>
  </model>
</sdf>
